Workbook

Sheet References
A1: cite_key | B1: author | C1: year | D1: title | E1: venue_or_publisher | F1: doi_or_url | G1: role
A2: beerling2018farming | B2: Beerling, David J. and Leake, Jonathan R. and Long, Stephen P. and Scholes, Julie D. and Ton, Jurriaan and Nelson, Paul N. and Bird, Michael and Kantzas, Euripides and Taylor, Lyla L. and Sarkar, Binoy and Kelland, Mike and DeLucia, Evan and Kantola, Ilsa and Muller, Christoph and Rau, Greg and Hansen, James | C2: 2018 | D2: Farming with crops and rocks to address global climate, food and soil security | E2: Nature Plants; vol. 4; pp. 138--147 | F2: doi:10.1038/s41477-018-0108-y | G2: In manuscript bibliography
A3: kelland2020increased | B3: Kelland, Mike E. and Wade, Peter W. and Lewis, Amy L. and Taylor, Lyla L. and Mayall, Michael and James, Rachael H. and Sheridan, James A. and Andrews, M. Grace and Sheridan, Michael and Sheridan, Terry M. and Pearce, Christopher R. and Sheridan, David and Epihov, Dimitar Z. and Sheridan, Andrew and Sheridan, Richard and Beerling, David J. | C3: 2020 | D3: Increased yield and CO$_2$ sequestration potential with the C$_4$ cereal \textitSorghum bicolor cultivated in basaltic rock dust-amended agricultural soil | E3: Global Change Biology; vol. 26; pp. 3658--3676 | F3: doi:10.1111/gcb.15089 | G3: In manuscript bibliography
A4: fao2015status | B4: FAO and ITPS | C4: 2015 | D4: Status of the World's Soil Resources (SWSR)—Main Report | E4: Food and Agriculture Organization of the United Nations and Intergovernmental Technical Panel on Soils | G4: In manuscript bibliography
A5: nsso2021sas77 | B5: National Statistical Office | C5: 2021 | D5: Situation Assessment of Agricultural Households and Land and Holdings of Households in Rural India, 2019 | E5: Ministry of Statistics and Programme Implementation, Government of India; SAS-77, covering agricultural year July 2018 to June 2019 | G5: In manuscript bibliography
A6: ricciardi2018smallholders | B6: Ricciardi, Vincent and Ramankutty, Navin and Mehrabi, Zia and Jarvis, Lian and Chookolingo, Brenton | C6: 2018 | D6: How much of the world's food do smallholders produce? | E6: Global Food Security; vol. 17; pp. 64--72 | F6: doi:10.1016/j.gfs.2017.10.001 | G6: In manuscript bibliography
A7: menegat2022greenhouse | B7: Menegat, Stefano and Ledo, Alicia and Tirado, Reyes | C7: 2022 | D7: Greenhouse gas emissions from global production and use of nitrogen synthetic fertilisers in agriculture | E7: Scientific Reports; vol. 12; pp. 14490 | F7: doi:10.1038/s41598-022-18773-w | G7: In manuscript bibliography
A8: isf2025smallholder | B8: ISF Advisors | C8: 2025 | D8: Beyond the Frontier: Decoding Viability in Smallholder Finance | E8: ISF Advisors | F8: https://isfadvisors.co/beyond-the-frontier-smallholder-finance/ | G8: In manuscript bibliography
A9: vanlauwe2014sustainable | B9: Vanlauwe, Bernard and Coyne, Danny and Gockowski, Jim and Hauser, Stefan and Huising, Jeroen and Masso, Cargele and Nziguheba, Generose and Schut, Marc and Van Asten, Piet | C9: 2014 | D9: Sustainable intensification and the African smallholder farmer | E9: Current Opinion in Environmental Sustainability; vol. 8; pp. 15--22 | F9: doi:10.1016/j.cosust.2014.06.001 | G9: In manuscript bibliography
A10: fao1993rice | B10: Juliano, Bienvenido O. | C10: 1993 | D10: Rice in Human Nutrition | E10: Food and Agriculture Organization of the United Nations; FAO Food and Nutrition Series | G10: In manuscript bibliography
A11: goi2019agcensus | B11: Government of India | C11: 2019 | D11: Agriculture Census 2015–16: All India Report on Number and Area of Operational Holdings | E11: Department of Agriculture, Cooperation and Farmers' Welfare, Ministry of Agriculture and Farmers' Welfare | G11: In manuscript bibliography
A12: gulati2015rationalising | B12: Gulati, Ashok and Banerjee, Pritha | C12: 2015 | D12: Rationalising Fertiliser Subsidy in India: Key Issues and Policy Options | E12: Indian Council for Research on International Economic Relations (ICRIER) | G12: In manuscript bibliography
A13: sapkota2025nitrogen | B13: Sapkota, Tek B. and Bijay-Singh | C13: 2025 | D13: India's fertilizer policies: implications for food security, environmental sustainability, and climate change | E13: Regional Environmental Change; vol. 25; pp. 63 | F13: doi:10.1007/s10113-025-02395-9 | G13: In manuscript bibliography
A14: ccea2025msp | B14: Cabinet Committee on Economic Affairs | C14: 2025 | D14: Cabinet approves Minimum Support Prices (MSP) for Kharif crops for Marketing Season 2025–26 | E14: Press Release, Press Information Bureau, Government of India | F14: https://www.pib.gov.in/PressReleasePage.aspx?PRID=2131983 | G14: In manuscript bibliography
A15: mospi2025cpi | B15: Ministry of Statistics and Programme Implementation | C15: 2025 | D15: Consumer Price Index Numbers on Base 2012=100 for Rural, Urban and Combined for the Month of October, 2025 | E15: National Statistical Office, Government of India | F15: https://www.mospi.gov.in | G15: Calculation input — not cited in manuscript text
A16: cgkuy2025 | B16: Government of Chhattisgarh | C16: 2025 | D16: Krishak Unnati Yojana: State paddy procurement bonus, Kharif Marketing Season 2025–26 | E16: Department of Food, Civil Supplies and Consumer Protection, Government of Chhattisgarh | G16: In manuscript bibliography
A17: jharkhandbonus2025 | B17: Government of Jharkhand | C17: 2025 | D17: State paddy procurement bonus of INR 81 per quintal, Kharif Marketing Season 2025–26 | E17: Department of Food, Public Distribution and Consumer Affairs, Government of Jharkhand | G17: In manuscript bibliography
A18: itinshwartz2026 | B18: Itin-Shwartz, Boaz | C18: 2026 | D18: Proportional payload allocation model for incremental transport cost attribution in smallholder agriculture | E18: Manuscript | G18: Calculation input — not cited in manuscript text
A19: nitiaayog2021 | B19: NITI Aayog | C19: 2021 | D19: Goods Transport Cost and Logistics Benchmarks in India | E19: NITI Aayog, Government of India | G19: Calculation input — not cited in manuscript text
A20: goi2025packaging | B20: Government of India | C20: 2025 | D20: Tender pricing for jute gunny bags (50 kg) for paddy procurement, Kharif Marketing Season 2025–26 | E20: Department of Food and Public Distribution, Ministry of Consumer Affairs, Food and Public Distribution | G20: Calculation input — not cited in manuscript text
A21: exchangerates2025 | B21: Exchange-Rates.org | C21: 2025 | D21: Indian Rupee to US Dollar (INR/USD) annual average exchange rate, 2025 | E21: Online | F21: https://www.exchange-rates.org/exchange-rate-history/inr-usd-2025 | G21: Calculation input — not cited in manuscript text

Sheet Assumptions
A1: PRICE ASSUMPTIONS — KMS 2025-26
A2: Central MSP, common paddy 2024-25 (INR/quintal) | B2: 2369 | E2: Source: CCEA (2024); Kharif Marketing Season 2024-25
A3: Exchange rate, 2025 annual average (INR/USD) | B3: 87.16 | E3: Source: Exchange-Rates.org; 2025 annual avg 1 USD = 87.159 INR
A4: Median yield uplift (%) | B4: 0.247 | E4: Source: This study; median dY from 216 Kharif paired measurements
A5: Baseline yield (Q/acre) | B5: 13.3 | E5: Source: This study; mean control plot yield across deployments
A7: STATE-LEVEL EFFECTIVE PROCUREMENT PRICES
B8: Chhattisgarh | C8: Madhya Pradesh | D8: Jharkhand
A9: State paddy bonus (INR/quintal) | B9: 731 | C9: 0 | D9: 81 | E9: CG: Krishak Unnati Yojana (GoC, 2024); MP: no per-quintal paddy bonus confirmed; JH: Cabinet Sep 2024, PTI/Cabinet Sec. Vandana Dadel
A10: Effective procurement price (INR/quintal) | B10: =$B$2+B9 -> 3100 | C10: =$B$2+C9 -> 2369 | D10: =$B$2+D9 -> 2450 | E10: Central MSP + state bonus
A11: Average operational holding (acres) | B11: 4 | C11: 3.9 | D11: 2.4 | E11: Source: Agriculture Census 2015-16; CG consistent with Jordan et al. deployment mean (3.44 ac)
A12: Annual HH income, SAS-77 (INR, 2018-19 nominal) | B12: 116124 | C12: 100068 | D12: 58740 | E12: Source: SAS-77 (NSO, 2021), PIB Release ID 1884228; monthly x 12
A13: Rural CPI, SAS-77 ref period (Base 2012=100) | B13: 140.9 | C13: 140.9 | D13: 140.9 | E13: Implied from paper Extended Data; CG uprated to ~164,000 INR
A14: Rural CPI, October 2025 (Base 2012=100) | B14: 199 | C14: 199 | D14: 199 | E14: Source: MoSPI, NSO (2025); Rural CPI October 2025
A15: CPI-uprated annual HH income (INR, 2025 prices) | B15: =B12*(B14/B13) -> 164007.64 | C15: =C12*(C14/C13) -> 141330.96 | D15: =D12*(D14/D13) -> 82961.391 | E15: Nominal HH income x (CPI Oct 2025 / CPI base period)
A16: CPI-uprated annual HH income (USD) | B16: =B15/$B$3 -> 1881.6847 | C16: =C15/$B$3 -> 1621.5117 | D16: =D15/$B$3 -> 951.82872 | E16: CPI-uprated HH income (INR) / exchange rate
A18: TRANSPORT & PACKAGING COST ASSUMPTIONS
A19: Transport distance (km) | B19: 20 | E19: Source: Itin-Shwartz (2026)
A20: Transport cost per km, 5t truck (INR/km) | B20: 35 | E20: Source: NITI Aayog (2021)
A21: Backhaul factor | B21: 2 | E21: Standard proportional payload allocation
A22: Packaging cost per 50kg bag (INR) | B22: 10.22 | E22: Source: GoI, Min Consumer Affairs (2025); KMS 2025-26
A24: Transport cost per tonne (INR/t) | B24: =B19*B20*B21 -> 1400 | E24: Distance x cost/km x backhaul factor

Sheet Net Income Calculation
A1: NET FARMER INCOME MODEL — ERW YIELD UPLIFT (KMS 2024-25)
B2: Chhattisgarh | C2: Madhya Pradesh | D2: Jharkhand | E2: Average
A3: INPUTS
A4: Effective procurement price (INR/Q) | B4: =Assumptions!B10 -> 3100 | C4: =Assumptions!C10 -> 2369 | D4: =Assumptions!D10 -> 2450
A5: Average farm size (acres) | B5: =Assumptions!B11 -> 4 | C5: =Assumptions!C11 -> 3.9 | D5: =Assumptions!D11 -> 2.4
A6: Baseline yield (Q/acre) | B6: =Assumptions!B5 -> 13.3 | C6: =Assumptions!B5 -> 13.3 | D6: =Assumptions!B5 -> 13.3
A7: Median yield uplift (%) | B7: =Assumptions!B4 -> 0.247 | C7: =Assumptions!B4 -> 0.247 | D7: =Assumptions!B4 -> 0.247
A9: PER-ACRE GROSS INCOME
A10: Yield uplift per acre (Q) | B10: =B6*B7 -> 3.2851 | C10: =C6*C7 -> 3.2851 | D10: =D6*D7 -> 3.2851
A11: Yield uplift per acre (kg) | B11: =B10*100 -> 328.51 | C11: =C10*100 -> 328.51 | D11: =D10*100 -> 328.51
A12: Gross added income per acre (INR) | B12: =B10*B4 -> 10183.81 | C12: =C10*C4 -> 7782.4019 | D12: =D10*D4 -> 8048.495
A13: Gross added income per acre (USD) | B13: =B12/Assumptions!$B$3 -> 116.84041 | C13: =C12/Assumptions!$B$3 -> 89.288686 | D13: =D12/Assumptions!$B$3 -> 92.341613
A15: PER-ACRE COST DEDUCTIONS
A16: Incremental yield per acre (tonnes) | B16: =B11/1000 -> 0.32851 | C16: =C11/1000 -> 0.32851 | D16: =D11/1000 -> 0.32851
A17: Transport cost per acre (INR) | B17: =B16*Assumptions!B24 -> 459.914 | C17: =C16*Assumptions!B24 -> 459.914 | D17: =D16*Assumptions!B24 -> 459.914
A18: Number of 50kg bags per acre | B18: =B11/50 -> 6.5702 | C18: =C11/50 -> 6.5702 | D18: =D11/50 -> 6.5702
A19: Packaging cost per acre (INR) | B19: =B18*Assumptions!B22 -> 67.147444 | C19: =C18*Assumptions!B22 -> 67.147444 | D19: =D18*Assumptions!B22 -> 67.147444
A20: Total deduction per acre (INR) | B20: =B17+B19 -> 527.06144 | C20: =C17+C19 -> 527.06144 | D20: =D17+D19 -> 527.06144
A21: Total deduction per acre (USD) | B21: =B20/Assumptions!$B$3 -> 6.0470565 | C21: =C20/Assumptions!$B$3 -> 6.0470565 | D21: =D20/Assumptions!$B$3 -> 6.0470565
A23: NET INCOME PER ACRE
A24: Net added income per acre (INR) | B24: =B12-B20 -> 9656.7486 | C24: =C12-C20 -> 7255.3405 | D24: =D12-D20 -> 7521.4336
A25: Net added income per acre (USD) | B25: =B24/Assumptions!$B$3 -> 110.79335 | C25: =C24/Assumptions!$B$3 -> 83.24163 | D25: =D24/Assumptions!$B$3 -> 86.294557
A27: PER-FARMER NET INCOME (SCALED TO HOLDING)
A28: Net added income per farmer (INR) | B28: =B24*B5 -> 38626.994 | C28: =C24*C5 -> 28295.828 | D28: =D24*D5 -> 18051.441
A29: Net added income per farmer (USD) | B29: =B28/Assumptions!$B$3 -> 443.17341 | C29: =C28/Assumptions!$B$3 -> 324.64236 | D29: =D28/Assumptions!$B$3 -> 207.10694
A31: CONTEXT
A32: Annual HH income, CPI-uprated (USD) | B32: =Assumptions!B16 -> 1881.6847 | C32: =Assumptions!C16 -> 1621.5117 | D32: =Assumptions!D16 -> 951.82872
A33: Net income per farmer as % of HH income | B33: =B29/B32 -> 0.23551949 | C33: =C29/C32 -> 0.20020969 | D33: =D29/D32 -> 0.21758845
A34: Deduction as % of gross (per acre) | B34: =B21/B13 -> 0.051754839 | C34: =C21/C13 -> 0.067724778 | D34: =D21/D13 -> 0.065485714
A36: METHODOLOGY
A37: 1. Net income = gross revenue from yield uplift minus incremental transport and packaging costs only.
A38: 2. Basalt is provided at no cost; cultivation practices unchanged; no other incremental costs incurred.
A39: 3. Transport: proportional payload model — d=20km, c=INR 35/km, 5t truck, backhaul factor=2 -> INR 1,400/tonne.
A40: 4. Packaging: INR 10.22 per 50kg bag (GoI revised rate, KMS 2025-26).
A41: 5. CG effective price: INR 3,100/Q (central MSP INR 2,300 + INR 800 Krishak Unnati Yojana bonus; GoC Food Dept).
A42: 6. MP effective price: INR 2,300/Q (central MSP only; no authoritative per-quintal paddy bonus confirmed for KMS 2024-25).
A43: 7. JH effective price: INR 2,400/Q (central MSP INR 2,300 + INR 100 state bonus; GoJ Cabinet Sep 2024, PTI).
A44: 8. Exchange rate: 87.16 INR/USD (2025 annual average; Exchange-Rates.org).
A45: 9. HH income: SAS-77 (NSO, 2021) CPI-uprated to 2025 prices using Rural CPI (Base 2012=100).
A46: 10. CPI base period: ~140.9 (implied from paper Extended Data); CPI Oct 2025: 199.0 (MoSPI, NSO).
...

Sheet Table 1
A1: Location | B1: N | C1: x̄ (%) | D1: x̃ (%) | E1: σ (%) | F1: A (ha) | G1: A (t ha⁻¹) | H1: M (t)
A2: GPM | B2: 85 | C2: 24.6 | D2: 23.5 | E2: 10.6 | F2: 3068 | G2: 16.4 | H2: 50427
A3: Seoni | B3: 83 | C3: 38.4 | D3: 34.6 | E3: 38.2 | F3: 2204 | G3: 25.7 | H3: 56634
A4: Pakur | B4: 32 | C4: 13.3 | D4: 12.2 | E4: 6.6 | F4: 1131 | G4: 25.3 | H4: 28566
A5: Nainpur | B5: 10 | C5: 33.2 | D5: 25 | E5: 24.1 | F5: 317 | G5: 18.1 | H5: 5755
A6: Shahdol | B6: 6 | C6: 54.7 | D6: 56.4 | E6: 18.3 | F6: 217 | G6: 17.4 | H6: 3775
A7: Total | B7: =SUM(B2:B6) -> 216 | C7: 29.5 | D7: 24.7 | E7: 27.1 | F7: =SUM(F2:F6) -> 6937 | H7: =SUM(H2:H6) -> 145157

Sheet Figure 1c
A1: farmer_id | B1: village_id | C1: mati_field_production | D1: base_id | E1: without_mati_field_production | F1: diff_production | G1: paddy_wt_mati_sqr_patch | H1: control_paddy_wt_mati_sqr_patch | I1: paddy_wt_diff | J1: Paddy weightwith Mati field in 1m-sq patch | K1: Paddy weight without Mati field in 1m-sq patch | L1: weight difference | M1: Percent Increase | N1: Crop_cut mati field production(quintal/Acre) | O1: Crop_cut control mati field production(quintal/Acre) | P1: Difference in production | Q1: Absolute Impact | R1: Acres | S1: Tonnage | T1: remarks | U1: Indicator | V1: Description | W1: Values | X1: Count of farmer_id
A2: 1726729433611 | B2: 55 | C2: 15.21 | D2: 1 | E2: 12.66 | F2: 2.55 | G2: 1.12 | H2: 0.93 | I2: 0.19 | J2: =G2/3 -> 0.37333333 | K2: =H2/3 -> 0.31 | L2: =J2-K2 -> 0.063333333 | M2: =L2/K2 -> 0.20430108 | N2: =J2*40.46856 -> 15.108262 | O2: =K2*40.46856 -> 12.545254 | P2: =N2-O2 -> 2.5630088 | Q2: =P2/O2 -> 0.20430108 | R2: =VLOOKUP(A2,'[1]Kharif tonnage acres2025'!A2:C1792,2,FALSE) -> 2.77 | S2: =VLOOKUP(A2,'[1]Kharif tonnage acres2025'!A1:C1792,3,FALSE) -> 30 | T2: Is farmer ko pichle saal ki tulna me is saal achha production mila hai. pichhale sal se is bar achha h abki is saal isme badhoti dekhne ko mili. Deployment me farmer ne 135 din wali variety lagayi hai, jiska performance is field me achha raha. Control me 120 din wali variety lagi thi, aur field thoda high-level par hone ki wajah se paani jama nahi ho paaya, isliye production kam aaya. | U2: Number of Farmers (N)(With both control and deployed plot) | V2: Total valid observations | W2: =GETPIVOTDATA("farmer_id",$X$1) -> 216 | X2: 216
A3: 1738229409347 | B3: 939 | C3: 20.5 | D3: 4 | E3: 18.5 | F3: 2 | G3: 0.51 | H3: 0.46 | I3: 0.05 | J3: =G3 -> 0.51 | K3: =H3 -> 0.46 | L3: =J3-K3 -> 0.05 | M3: =L3/K3 -> 0.10869565 | N3: =J3*40.46856 -> 20.638966 | O3: =K3*40.46856 -> 18.615538 | P3: =N3-O3 -> 2.023428 | Q3: =P3/O3 -> 0.10869565 | R3: =VLOOKUP(A3,'[1]Kharif tonnage acres2025'!A3:C1793,2,FALSE) -> 0 | S3: =VLOOKUP(A3,'[1]Kharif tonnage acres2025'!A2:C1793,3,FALSE) -> 6.55 | T3: is varsh dhaan ka quality achcha hai and dhaan ka vajan bhi achcha hai. | U3: Avg Deployed Yield (q/acre) | V3: Mean yield under MATI | W3: =AVERAGE(N:N) -> 16.762602
A4: 1738231639812 | B4: 939 | C4: 16 | D4: 4 | E4: 14.5 | F4: 1.5 | G4: 0.4 | H4: 0.36 | I4: 0.04 | J4: =G4 -> 0.4 | K4: =H4 -> 0.36 | L4: =J4-K4 -> 0.04 | M4: =L4/K4 -> 0.11111111 | N4: =J4*40.46856 -> 16.187424 | O4: =K4*40.46856 -> 14.568682 | P4: =N4-O4 -> 1.6187424 | Q4: =P4/O4 -> 0.11111111 | R4: =VLOOKUP(A4,'[1]Kharif tonnage acres2025'!A4:C1794,2,FALSE) -> 0 | S4: =VLOOKUP(A4,'[1]Kharif tonnage acres2025'!A3:C1794,3,FALSE) -> 6.77 | T4: is varsh Khet ka dhaan bahut Achcha Hua Hai dhaan ka color bhi bahut Sundar Hai dhaan ka vajan pichhle varshon ki tulna mein is varsh jyada hai. | U4: Avg Control Yield (q/acre) | V4: Mean yield without MATI | W4: =AVERAGE(O:O) -> 13.273438
A5: 1747200300435 | B5: 7 | C5: 13.75 | D5: 1 | E5: 9.3 | F5: 4.45 | G5: 1.02 | H5: 0.69 | I5: 0.33 | J5: =G5/3 -> 0.34 | K5: =H5/3 -> 0.23 | L5: =J5-K5 -> 0.11 | M5: =L5/K5 -> 0.47826087 | N5: =J5*40.46856 -> 13.75931 | O5: =K5*40.46856 -> 9.3077688 | P5: =N5-O5 -> 4.4515416 | Q5: =P5/O5 -> 0.47826087 | R5: =VLOOKUP(A5,'[1]Kharif tonnage acres2025'!A5:C1795,2,FALSE) -> 41.45 | S5: =VLOOKUP(A5,'[1]Kharif tonnage acres2025'!A4:C1795,3,FALSE) -> 435 | T5: किसान ने बताया की उसकी फसल अच्छा है और अच्छी उपज मिलने की बात कही है | U5: Avg Yield Difference (q/acre) | V5: Mean gain per farmer | W5: =AVERAGE(P:P) -> 3.4891643
A6: 1744694039008 | B6: 939 | C6: 17 | D6: 4 | E6: 16 | F6: 1 | G6: 0.42 | H6: 0.39 | I6: 0.03 | J6: =G6 -> 0.42 | K6: =H6 -> 0.39 | L6: =J6-K6 -> 0.03 | M6: =L6/K6 -> 0.076923077 | N6: =J6*40.46856 -> 16.996795 | O6: =K6*40.46856 -> 15.782738 | P6: =N6-O6 -> 1.2140568 | Q6: =P6/O6 -> 0.076923077 | R6: =VLOOKUP(A6,'[1]Kharif tonnage acres2025'!A6:C1796,2,FALSE) -> 0 | S6: =VLOOKUP(A6,'[1]Kharif tonnage acres2025'!A5:C1796,3,FALSE) -> 7.62 | T6: jis Khet mein Mati purak lagaye Hain usmein achcha dhaan hua Hai aur paraali bhi achcha dikhta Hai aur lamba hai jis Khet mein Mati purak nahin lagaye Hain uski tulna mein aage bhi Kisan matipura ka prayog karne ki ichcha jahir karta hai | U6: Avg Yield Impact (%) | V6: Mean % change | W6: =AVERAGE(Q:Q) -> 0.29468797
A7: 1730526661966 | B7: 7 | C7: 13.59 | D7: 1 | E7: 10.43 | F7: 3.16 | G7: 1 | H7: 0.77 | I7: 0.23 | J7: =G7/3 -> 0.33333333 | K7: =H7/3 -> 0.25666667 | L7: =J7-K7 -> 0.076666667 | M7: =L7/K7 -> 0.2987013 | N7: =J7*40.46856 -> 13.48952 | O7: =K7*40.46856 -> 10.38693 | P7: =N7-O7 -> 3.1025896 | Q7: =P7/O7 -> 0.2987013 | R7: =VLOOKUP(A7,'[1]Kharif tonnage acres2025'!A7:C1797,2,FALSE) -> 14.32 | S7: =VLOOKUP(A7,'[1]Kharif tonnage acres2025'!A6:C1797,3,FALSE) -> 145 | T7: phasal achha hai | U7: Median Yield Impact (%) | V7: Robust % impact | W7: =MEDIAN(Q:Q) -> 0.24705882
A8: 1738306257831 | B8: 939 | C8: 18 | D8: 4 | E8: 16.5 | F8: 1.5 | G8: 0.45 | H8: 0.41 | I8: 0.04 | J8: =G8 -> 0.45 | K8: =H8 -> 0.41 | L8: =J8-K8 -> 0.04 | M8: =L8/K8 -> 0.097560976 | N8: =J8*40.46856 -> 18.210852 | O8: =K8*40.46856 -> 16.59211 | P8: =N8-O8 -> 1.6187424 | Q8: =P8/O8 -> 0.097560976 | R8: =VLOOKUP(A8,'[1]Kharif tonnage acres2025'!A8:C1798,2,FALSE) -> 0 | S8: =VLOOKUP(A8,'[1]Kharif tonnage acres2025'!A7:C1798,3,FALSE) -> 11.6 | T8: is varsh mati diploy field mein dhaan bahut achcha tha jisse dhaan ka quality bahut behtar hua hai aur dhaan ka vajan bhi bahut jyada badha hua Hai. | U8: Trimmed Mean Impact (%) | V8: Impact excluding extremes | W8: =TRIMMEAN(Q:Q,0.05) -> 0.2820283
A9: 1726041387616 | B9: 3 | C9: 13.67 | D9: 1 | E9: 12.38 | F9: 1.29 | G9: 1.04 | H9: 0.91 | I9: 0.96 | J9: =G9/3 -> 0.34666667 | K9: =H9/3 -> 0.30333333 | L9: =J9-K9 -> 0.043333333 | M9: =L9/K9 -> 0.14285714 | N9: =J9*40.46856 -> 14.029101 | O9: =K9*40.46856 -> 12.275463 | P9: =N9-O9 -> 1.7536376 | Q9: =P9/O9 -> 0.14285714 | R9: =VLOOKUP(A9,'[1]Kharif tonnage acres2025'!A9:C1799,2,FALSE) -> 9.09 | S9: =VLOOKUP(A9,'[1]Kharif tonnage acres2025'!A8:C1799,3,FALSE) -> 100 | T9: माटी पूरक का प्रभाव शानदार रहा कीट रोग में कमी आयाकल्ले की संख्या मे वृद्धि और बालियों की लंबाई मे वृद्धि देखा गया दाना वजनदार दिख रहा है। Is farmer ko pichle saal ki tulna me is saal achha production mila hai. Pichle saal inka production 12 Q tha, jabki is saal isme badhoti dekhne ko mili. | U9: Min Impact (%) | V9: Worst observed impact | W9: =MIN(Q:Q) -> -0.43902439
A10: 1727151811431 | B10: 55 | C10: 18.28 | D10: 1 | E10: 14.52 | F10: 3.76 | G10: 1.35 | H10: 1.07 | I10: 0.28 | J10: =G10/3 -> 0.45 | K10: =H10/3 -> 0.35666667 | L10: =J10-K10 -> 0.093333333 | M10: =L10/K10 -> 0.26168224 | N10: =J10*40.46856 -> 18.210852 | O10: =K10*40.46856 -> 14.433786 | P10: =N10-O10 -> 3.7770656 | Q10: =P10/O10 -> 0.26168224 | R10: =VLOOKUP(A10,'[1]Kharif tonnage acres2025'!A10:C1800,2,FALSE) -> 11.73 | S10: =VLOOKUP(A10,'[1]Kharif tonnage acres2025'!A9:C1800,3,FALSE) -> 125 | T10: उत्पादन अच्छा हुआ है, कीट रोग की समस्या में कमी आया है, दाना वजनदार है. Pichle varsh farmer ka yield kam tha, lekin is saal me behtar hasil mila. Deployment plot me same fertilizer treatment diya gaya, jis se crop health acche se maintained rahi. Control plot me pani ka flow irregular tha, jiski wajah se production utna nahi ho saka. | U10: Max Impact (%) | V10: Best observed impact | W10: =MAX(Q:Q) -> 2
A11: 1744620291141 | B11: 1094 | C11: 28.32 | D11: 13 | E11: 16.18 | F11: 12.14 | G11: 0.7 | H11: 0.4 | I11: 0.3 | J11: =G11 -> 0.7 | K11: =H11 -> 0.4 | L11: =J11-K11 -> 0.3 | M11: =L11/K11 -> 0.75 | N11: =J11*40.46856 -> 28.327992 | O11: =K11*40.46856 -> 16.187424 | P11: =N11-O11 -> 12.140568 | Q11: =P11/O11 -> 0.75 | R11: 6.21 | S11: 65 | T11: 1. En Farmer ko pechle varsh ki apech kafi jada production mil hai. Pichele varsh enke production 24 Q hui thi. 2. En Farmer ne Depolyment me 135 din wali dhaan lagaya hai joki achhi uhi hai 3. Control me 120 din wali dhaan lagi the aur yah field upper stream per hone se in field se pani me rukao nahi hone se dhaan me production kam hua. | U11: Max Yield Deployed Plot(q/acre) | V11: From Crop Cut | W11: =MAX(N:N) -> 101.1714
A12: 1743844344980 | B12: 107 | C12: 13.31 | D12: 1 | E12: 9.83 | F12: 3.48 | G12: 0.98 | H12: 0.72 | I12: 0.26 | J12: =G12/3 -> 0.32666667 | K12: =H12/3 -> 0.24 | L12: =J12-K12 -> 0.086666667 | M12: =L12/K12 -> 0.36111111 | N12: =J12*40.46856 -> 13.21973 | O12: =K12*40.46856 -> 9.7124544 | P12: =N12-O12 -> 3.5072752 | Q12: =P12/O12 -> 0.36111111 | R12: 5.36 | S12: =VLOOKUP(A12,'[1]Kharif tonnage acres2025'!A11:C1802,3,FALSE) -> 100 | T12: Is farmer ko pichle saal ki tulna me is saal achha production mila hai. Pichle saal inka production10 Q tha, jabki is saal isme badhoti dekhne ko mili. Deployment me farmer ne 120 din wali variety lagayi hai, jiska performance is field me achha raha. Control me 120 din wali variety lagi thi, aur field thoda high-level par hone ki wajah se paani jama nahi ho paaya, isliye production kam aaya. | U12: Min Yield Deployed Plot(q/acre) | V12: From Crop Cut | W12: =MIN(N:N) -> 6.4749696
A13: 1733721019866 | B13: 845 | C13: 24.5 | D13: 2 | E13: 17.5 | F13: 7 | G13: 0.6 | H13: 0.44 | I13: 0.16 | J13: =G13 -> 0.6 | K13: =H13 -> 0.44 | L13: =J13-K13 -> 0.16 | M13: =L13/K13 -> 0.36363636 | N13: =J13*40.46856 -> 24.281136 | O13: =K13*40.46856 -> 17.806166 | P13: =N13-O13 -> 6.4749696 | Q13: =P13/O13 -> 0.36363636 | R13: 15.94 | S13: =VLOOKUP(A13,'[1]Kharif tonnage acres2025'!A12:C1803,3,FALSE) -> 100 | T13: 1. मिट्टी पूरक का बहुत अच्छा प्रभाव रहा है। 2. इस वर्ष किसी भी प्रकार की बीमारी नहीं लगी है। 3. रासायनिक खाद का कम उपयोग करने के बावजूद फसल का बढ़ाव अच्छा हुआ है और उत्पादन भी अच्छा होने की संभावना है।
A14: 1748500587905 | B14: 1094 | C14: 24.28 | D14: 13 | E14: 19.82 | F14: 4.46 | G14: 0.6 | H14: 0.49 | I14: 0.11 | J14: =G14 -> 0.6 | K14: =H14 -> 0.49 | L14: =J14-K14 -> 0.11 | M14: =L14/K14 -> 0.2244898 | N14: =J14*40.46856 -> 24.281136 | O14: =K14*40.46856 -> 19.829594 | P14: =N14-O14 -> 4.4515416 | Q14: =P14/O14 -> 0.2244898 | R14: 10.56 | S14: 50 | T14: 1. Pichale Varsh ki utpadan 22 Q hua tha, es varsh 2 Q ki virdhi hui hai. 2. Deployment khet ki dhaan control se achhi hue hai. 3. control ki agrowaste gilli wastha me hai aur Deployment ki dry hai, is wajas se control agrowaste weight jada hua.
A15: 1715928719043 | B15: 845 | C15: 13.3 | D15: 2 | E15: 11.3 | F15: 2 | G15: 0.33 | H15: 0.28 | I15: 0.05 | J15: =G15 -> 0.33 | K15: =H15 -> 0.28 | L15: =J15-K15 -> 0.05 | M15: =L15/K15 -> 0.17857143 | N15: =J15*40.46856 -> 13.354625 | O15: =K15*40.46856 -> 11.331197 | P15: =N15-O15 -> 2.023428 | Q15: =P15/O15 -> 0.17857143 | R15: 11.58 | S15: =VLOOKUP(A15,'[1]Kharif tonnage acres2025'!A14:C1805,3,FALSE) -> 95 | T15: Fasal badiya bani thi or growth bi achi huyi thi jis karan se Control plot mai upaj kham or Deployed polt mai upja jada nikli hai
A16: 1727518386307 | B16: 7 | C16: 12.98 | D16: 1 | E16: 10.56 | F16: 2.42 | G16: 0.96 | H16: 0.78 | I16: 0.18 | J16: =G16/3 -> 0.32 | K16: =H16/3 -> 0.26 | L16: =J16-K16 -> 0.06 | M16: =L16/K16 -> 0.23076923 | N16: =J16*40.46856 -> 12.949939 | O16: =K16*40.46856 -> 10.521826 | P16: =N16-O16 -> 2.4281136 | Q16: =P16/O16 -> 0.23076923 | R16: 12.51 | S16: =VLOOKUP(A16,'[1]Kharif tonnage acres2025'!A15:C1806,3,FALSE) -> 210 | T16: phasal gunvatta kafi achha h
A17: 1729140634986 | B17: 132 | C17: 14.32 | D17: 1 | E17: 11.97 | F17: 2.35 | G17: 1.06 | H17: 0.88 | I17: 0.18 | J17: =G17/3 -> 0.35333333 | K17: =H17/3 -> 0.29333333 | L17: =J17-K17 -> 0.06 | M17: =L17/K17 -> 0.20454545 | N17: =J17*40.46856 -> 14.298891 | O17: =K17*40.46856 -> 11.870778 | P17: =N17-O17 -> 2.4281136 | Q17: =P17/O17 -> 0.20454545 | R17: 4.44 | S17: =VLOOKUP(A17,'[1]Kharif tonnage acres2025'!A16:C1807,3,FALSE) -> 200 | T17: Deployment plot me same variety lagayi gayi hai, aur is par sahi samay par pani aur poshan mila.
A18: 1736148507326 | B18: 132 | C18: 12.54 | D18: 1 | E18: 11.53 | F18: 1.01 | G18: 0.93 | H18: 0.85 | I18: 0.08 | J18: =G18/3 -> 0.31 | K18: =H18/3 -> 0.28333333 | L18: =J18-K18 -> 0.026666667 | M18: =L18/K18 -> 0.094117647 | N18: =J18*40.46856 -> 12.545254 | O18: =K18*40.46856 -> 11.466092 | P18: =N18-O18 -> 1.0791616 | Q18: =P18/O18 -> 0.094117647 | R18: 7.63 | S18: =VLOOKUP(A18,'[1]Kharif tonnage acres2025'!A17:C1808,3,FALSE) -> 90 | T18: किसान का उत्पादन अच्छा हुआ है एवं माटी पूरक डालने के बाद उत्पादन में वृद्धि भी हुई है
A19: 2126 | B19: 132 | C19: 12.66 | D19: 1 | E19: 11.73 | F19: 0.93 | G19: 0.93 | H19: 0.87 | I19: 0.06 | J19: =G19/3 -> 0.31 | K19: =H19/3 -> 0.29 | L19: =J19-K19 -> 0.02 | M19: =L19/K19 -> 0.068965517 | N19: =J19*40.46856 -> 12.545254 | O19: =K19*40.46856 -> 11.735882 | P19: =N19-O19 -> 0.8093712 | Q19: =P19/O19 -> 0.068965517 | R19: 9.44 | S19: =VLOOKUP(A19,'[1]Kharif tonnage acres2025'!A18:C1809,3,FALSE) -> 260 | T19: Control me 120 din wali variety lagi thi, aur field thoda high-level par hone ki wajah se paani jama nahi ho paaya, isliye production kam aaya.
A20: 1725600601253 | B20: 3 | C20: 15.17 | D20: 1 | E20: 12.86 | F20: 2.31 | G20: 1.12 | H20: 0.95 | I20: 0.17 | J20: =G20/3 -> 0.37333333 | K20: =H20/3 -> 0.31666667 | L20: =J20-K20 -> 0.056666667 | M20: =L20/K20 -> 0.17894737 | N20: =J20*40.46856 -> 15.108262 | O20: =K20*40.46856 -> 12.815044 | P20: =N20-O20 -> 2.2932184 | Q20: =P20/O20 -> 0.17894737 | R20: 4.81 | S20: =VLOOKUP(A20,'[1]Kharif tonnage acres2025'!A19:C1810,3,FALSE) -> 200 | T20: Pichle varsh ke mukable is saal farmer ka production behtar raha. Pichle saal 13 Q tha, is saal me vriddhi dekhi gayi. Deployment plot me same variety lagayi gayi hai, aur is par sahi samay par pani aur poshan mila. Control plot me paani ki kami ke karan plant growth prabhavit hui, jisse utpaadan me kami rahi.
A21: 1750057272690 | B21: 855 | C21: 17.5 | D21: 4 | E21: 16 | F21: 1.5 | G21: 0.43 | H21: 0.39 | I21: 0.04 | J21: =G21 -> 0.43 | K21: =H21 -> 0.39 | L21: =J21-K21 -> 0.04 | M21: =L21/K21 -> 0.1025641 | N21: =J21*40.46856 -> 17.401481 | O21: =K21*40.46856 -> 15.782738 | P21: =N21-O21 -> 1.6187424 | Q21: =P21/O21 -> 0.1025641 | R21: 8.36 | S21: =VLOOKUP(A21,'[1]Kharif tonnage acres2025'!A20:C1811,3,FALSE) -> 1.63 | T21: Jis Khet mein Mati purak lagaya hai usmein jyada Dhan hua Hai control field ki tulna mein aage bhi matipurak ka prayog Apne kheto mein karenge Kisan
A22: 1730182354607 | B22: 124 | C22: 11.73 | D22: 1 | E22: 9.29 | F22: 2.44 | G22: 0.87 | H22: 0.69 | I22: 0.18 | J22: =G22/3 -> 0.29 | K22: =H22/3 -> 0.23 | L22: =J22-K22 -> 0.06 | M22: =L22/K22 -> 0.26086957 | N22: =J22*40.46856 -> 11.735882 | O22: =K22*40.46856 -> 9.3077688 | P22: =N22-O22 -> 2.4281136 | Q22: =P22/O22 -> 0.26086957 | R22: 8.74 | S22: =VLOOKUP(A22,'[1]Kharif tonnage acres2025'!A21:C1812,3,FALSE) -> 85 | T22: फसल काफी अच्छा था उपज भी पिछले साल की अपेक्षा अधिक मिल सकती है
A23: 1743486604944 | B23: 1038 | C23: 17 | D23: 4 | E23: 15 | F23: 2 | G23: 0.42 | H23: 0.37 | I23: 0.05 | J23: =G23 -> 0.42 | K23: =H23 -> 0.37 | L23: =J23-K23 -> 0.05 | M23: =L23/K23 -> 0.13513514 | N23: =J23*40.46856 -> 16.996795 | O23: =K23*40.46856 -> 14.973367 | P23: =N23-O23 -> 2.023428 | Q23: =P23/O23 -> 0.13513514 | R23: 12.07 | S23: =VLOOKUP(A23,'[1]Kharif tonnage acres2025'!A22:C1813,3,FALSE) -> 7.39 | T23: Jis Khet mein Mati dala hai usmein achcha dhan hua hai aur parali bhi Mota ,Lamba hua Hai control field ki tulna mein
A24: 1738129011868 | B24: 939 | C24: 17 | D24: 4 | E24: 14 | F24: 3 | G24: 0.43 | H24: 0.34 | I24: 0.09 | J24: =G24 -> 0.43 | K24: =H24 -> 0.34 | L24: =J24-K24 -> 0.09 | M24: =L24/K24 -> 0.26470588 | N24: =J24*40.46856 -> 17.401481 | O24: =K24*40.46856 -> 13.75931 | P24: =N24-O24 -> 3.6421704 | Q24: =P24/O24 -> 0.26470588 | R24: 11.76 | S24: =VLOOKUP(A24,'[1]Kharif tonnage acres2025'!A23:C1814,3,FALSE) -> 3.48 | T24: is sal fasal ka vajan aur quality achcha hai ,
A25: 1725951396481 | B25: 3 | C25: 14.24 | D25: 1 | E25: 12.46 | F25: 1.78 | G25: 1.05 | H25: 0.92 | I25: 0.13 | J25: =G25/3 -> 0.35 | K25: =H25/3 -> 0.30666667 | L25: =J25-K25 -> 0.043333333 | M25: =L25/K25 -> 0.14130435 | N25: =J25*40.46856 -> 14.163996 | O25: =K25*40.46856 -> 12.410358 | P25: =N25-O25 -> 1.7536376 | Q25: =P25/O25 -> 0.14130435 | R25: 11.49 | S25: =VLOOKUP(A25,'[1]Kharif tonnage acres2025'!A24:C1815,3,FALSE) -> 245 | T25: Pichle varsh ke mukable is saal farmer ka production behtar raha. Pichle saal 13 Q tha, is saal me vriddhi dekhi gayi. Deployment plot me same variety lagayi gayi hai, aur is par sahi samay par pani aur poshan mila. Control plot me paani ki kami ke karan plant growth prabhavit hui, jisse utpaadan me kami rahi.
A26: 1714709737320 | B26: 769 | C26: 11 | D26: 2 | E26: 9 | F26: 2 | G26: 0.28 | H26: 0.22 | I26: 0.05 | J26: =G26 -> 0.28 | K26: =H26 -> 0.22 | L26: =J26-K26 -> 0.06 | M26: =L26/K26 -> 0.27272727 | N26: =J26*40.46856 -> 11.331197 | O26: =K26*40.46856 -> 8.9030832 | P26: =N26-O26 -> 2.4281136 | Q26: =P26/O26 -> 0.27272727 | R26: 7.8 | S26: =VLOOKUP(A26,'[1]Kharif tonnage acres2025'!A25:C1816,3,FALSE) -> 60 | T26: kisan ko basalt se Jo fayde dikhe hai vo is prakar hai 1. deployed plot me fasal vajandar hai jabki control plot ki fasal ka vajan Kam hai 2. deployed plot me poudhe harvesting tak gire nahi jabki control plot ke poudhe harvesting ke pehle hi gir gye the
A27: 1744016112133 | B27: 1038 | C27: 17 | D27: 4 | E27: 14 | F27: 3 | G27: 0.42 | H27: 0.35 | I27: 0.07 | J27: =G27 -> 0.42 | K27: =H27 -> 0.35 | L27: =J27-K27 -> 0.07 | M27: =L27/K27 -> 0.2 | N27: =J27*40.46856 -> 16.996795 | O27: =K27*40.46856 -> 14.163996 | P27: =N27-O27 -> 2.8327992 | Q27: =P27/O27 -> 0.2 | R27: =VLOOKUP(A27,'[1]Kharif tonnage acres2025'!A27:C1817,2,FALSE) -> 0 | S27: =VLOOKUP(A27,'[1]Kharif tonnage acres2025'!A26:C1817,3,FALSE) -> 6.69 | T27: Jis Jis Khet mein Mati purak dala hai usmein jyada Dhan hua Hai jismein nahin dala hai uski tulna mein
A28: 2625 | B28: 739 | C28: 13.95 | D28: 1 | E28: 11.85 | F28: 2.1 | G28: 1.03 | H28: 0.87 | I28: 0.16 | J28: =G28/3 -> 0.34333333 | K28: =H28/3 -> 0.29 | L28: =J28-K28 -> 0.053333333 | M28: =L28/K28 -> 0.18390805 | N28: =J28*40.46856 -> 13.894206 | O28: =K28*40.46856 -> 11.735882 | P28: =N28-O28 -> 2.1583232 | Q28: =P28/O28 -> 0.18390805 | R28: =VLOOKUP(A28,'[1]Kharif tonnage acres2025'!A28:C1818,2,FALSE) -> 18.92 | S28: =VLOOKUP(A28,'[1]Kharif tonnage acres2025'!A27:C1818,3,FALSE) -> 190 | T28: control field ke apechha mati field me utapadan me badotri hua hai
A29: 1746455992733 | B29: 939 | C29: 16 | D29: 4 | E29: 12 | F29: 0.4 | G29: 0.4 | H29: 0.3 | I29: 0.1 | J29: =G29 -> 0.4 | K29: =H29 -> 0.3 | L29: =J29-K29 -> 0.1 | M29: =L29/K29 -> 0.33333333 | N29: =J29*40.46856 -> 16.187424 | O29: =K29*40.46856 -> 12.140568 | P29: =N29-O29 -> 4.046856 | Q29: =P29/O29 -> 0.33333333 | R29: =VLOOKUP(A29,'[1]Kharif tonnage acres2025'!A29:C1819,2,FALSE) -> 0 | S29: =VLOOKUP(A29,'[1]Kharif tonnage acres2025'!A28:C1819,3,FALSE) -> 11.8 | T29: Kisan bahut khush hai jis Khet mein matipur lagaya hai usmein achcha Dan hua Hai aur uska Kunal bhi achcha hua Hai jis Khet mein matipura nahin lagaya uske tulna mein aur Kisan aage bhi matipura ka prayog karna chahta hai
A30: 1745481111010 | B30: 1094 | C30: 21.44 | D30: 13 | E30: 13.75 | F30: 7.69 | G30: 0.53 | H30: 0.34 | I30: 0.19 | J30: =G30 -> 0.53 | K30: =H30 -> 0.34 | L30: =J30-K30 -> 0.19 | M30: =L30/K30 -> 0.55882353 | N30: =J30*40.46856 -> 21.448337 | O30: =K30*40.46856 -> 13.75931 | P30: =N30-O30 -> 7.6890264 | Q30: =P30/O30 -> 0.55882353 | R30: 15.94 | S30: 145 | T30: 1.Pichale Varsh ki apekcha ish Saal fasal me vradhi hui hai 2.Control field me bimari lgne se dhan tut kar jhad gya jisse control field me kami aai 3.mati field par bimari nahi lagi 4.barish ka pani paryap hone se fasal achhi jabki pichale satra me ek pani ki wjah se kam hui thi
A31: 1745495962758 | B31: 939 | C31: 21 | D31: 4 | E31: 16 | F31: 5 | G31: 0.52 | H31: 0.4 | I31: 0.12 | J31: =G31 -> 0.52 | K31: =H31 -> 0.4 | L31: =J31-K31 -> 0.12 | M31: =L31/K31 -> 0.3 | N31: =J31*40.46856 -> 21.043651 | O31: =K31*40.46856 -> 16.187424 | P31: =N31-O31 -> 4.8562272 | Q31: =P31/O31 -> 0.3 | R31: 10.56 | S31: =VLOOKUP(A31,'[1]Kharif tonnage acres2025'!A30:C1821,3,FALSE) -> 7.6 | T31: mati purak lagane ke bad Khet mein bahut sare Parivartan dikhai diye dhaan bhi achcha hua Hai aur iska pwal bhi achcha hua Hai Kisan khush hai
A32: 1727419104712 | B32: 7 | C32: 21.64 | D32: 1 | E32: 15.77 | F32: 5.87 | G32: 1.6 | H32: 1.17 | I32: 0.43 | J32: =G32/3 -> 0.53333333 | K32: =H32/3 -> 0.39 | L32: =J32-K32 -> 0.14333333 | M32: =L32/K32 -> 0.36752137 | N32: =J32*40.46856 -> 21.583232 | O32: =K32*40.46856 -> 15.782738 | P32: =N32-O32 -> 5.8004936 | Q32: =P32/O32 -> 0.36752137 | R32: 11.58 | S32: =VLOOKUP(A32,'[1]Kharif tonnage acres2025'!A31:C1822,3,FALSE) -> 150 | T32: किसान का फसल काफी अच्छा है उपज भी पिछले साल की अपेक्षा अधिक होने की बात किसान ने कही है
A33: 1727518510122 | B33: 7 | C33: 17.6 | D33: 1 | E33: 11.73 | F33: 5.87 | G33: 1.3 | H33: 0.87 | I33: 0.43 | J33: =G33/3 -> 0.43333333 | K33: =H33/3 -> 0.29 | L33: =J33-K33 -> 0.14333333 | M33: =L33/K33 -> 0.49425287 | N33: =J33*40.46856 -> 17.536376 | O33: =K33*40.46856 -> 11.735882 | P33: =N33-O33 -> 5.8004936 | Q33: =P33/O33 -> 0.49425287 | R33: 12.51 | S33: =VLOOKUP(A33,'[1]Kharif tonnage acres2025'!A32:C1823,3,FALSE) -> 265 | T33: किसान के फसल में किसी प्रकार से रोग आदि नहीं लगा था और किसान ने बताया की इस साल अच्छी उपज मिल सकती है
A34: 1743575791892 | B34: 1041 | C34: 16.5 | D34: 4 | E34: 14.5 | F34: 2 | G34: 0.41 | H34: 0.36 | I34: 0.05 | J34: =G34 -> 0.41 | K34: =H34 -> 0.36 | L34: =J34-K34 -> 0.05 | M34: =L34/K34 -> 0.13888889 | N34: =J34*40.46856 -> 16.59211 | O34: =K34*40.46856 -> 14.568682 | P34: =N34-O34 -> 2.023428 | Q34: =P34/O34 -> 0.13888889 | R34: 4.44 | S34: =VLOOKUP(A34,'[1]Kharif tonnage acres2025'!A33:C1824,3,FALSE) -> 12.34 | T34: Jis Khet mein matipurak dala hai usmein jyada dhan hua Hai aur parale bhi Lamba or Mota hua Hai
A35: 1744868280333 | B35: 939 | C35: 16 | D35: 4 | E35: 15 | F35: 1 | G35: 0.4 | H35: 0.38 | I35: 0.02 | J35: =G35 -> 0.4 | K35: =H35 -> 0.38 | L35: =J35-K35 -> 0.02 | M35: =L35/K35 -> 0.052631579 | N35: =J35*40.46856 -> 16.187424 | O35: =K35*40.46856 -> 15.378053 | P35: =N35-O35 -> 0.8093712 | Q35: =P35/O35 -> 0.052631579 | R35: 7.63 | S35: =VLOOKUP(A35,'[1]Kharif tonnage acres2025'!A34:C1825,3,FALSE) -> 19.38 | T35: is bar Mati diploy karne ke bad Khet ka Mitti mein bahut Sudhar Hua Hai isse dhaan ka quality bahut behtar Hua Hai and dhaan ka vajan bhi bahut jyada hua hai.
A36: 1728631791144 | B36: 107 | C36: 14.36 | D36: 1 | E36: 11.57 | F36: 2.79 | G36: 1.06 | H36: 0.85 | I36: 0.21 | J36: =G36/3 -> 0.35333333 | K36: =H36/3 -> 0.28333333 | L36: =J36-K36 -> 0.07 | M36: =L36/K36 -> 0.24705882 | N36: =J36*40.46856 -> 14.298891 | O36: =K36*40.46856 -> 11.466092 | P36: =N36-O36 -> 2.8327992 | Q36: =P36/O36 -> 0.24705882 | R36: 9.44 | S36: =VLOOKUP(A36,'[1]Kharif tonnage acres2025'!A35:C1826,3,FALSE) -> 100 | T36: Is farmer ko pichle saal ki tulna me is saal achha production mila hai. Pichle saal inka production 12 Q tha, jabki is saal isme badhoti dekhne ko mili. Deployment me farmer ne 120 din wali variety lagayi hai, jiska performance is field me achha raha. Control me 120 din wali variety lagi thi, aur field thoda high-level par hone ki wajah se paani jama nahi ho paaya, isliye production kam aaya.
A37: 1744782908107 | B37: 939 | C37: 16.5 | D37: 4 | E37: 14.5 | F37: 2 | G37: 0.41 | H37: 0.36 | I37: 0.05 | J37: =G37 -> 0.41 | K37: =H37 -> 0.36 | L37: =J37-K37 -> 0.05 | M37: =L37/K37 -> 0.13888889 | N37: =J37*40.46856 -> 16.59211 | O37: =K37*40.46856 -> 14.568682 | P37: =N37-O37 -> 2.023428 | Q37: =P37/O37 -> 0.13888889 | R37: 4.81 | S37: =VLOOKUP(A37,'[1]Kharif tonnage acres2025'!A36:C1827,3,FALSE) -> 8.07 | T37: Jis Jis Khet mein matepurak dala hai usmein jyada Dhanu Hai jismein nahin dala hai uske tulna mein aur aage bhi matipura ka prayog Kisan Apne kheton mein karenge
A38: 1746189360599 | B38: 939 | C38: 18 | D38: 4 | E38: 16 | F38: 2 | G38: 0.44 | H38: 0.39 | I38: 0.05 | J38: =G38 -> 0.44 | K38: =H38 -> 0.39 | L38: =J38-K38 -> 0.05 | M38: =L38/K38 -> 0.12820513 | N38: =J38*40.46856 -> 17.806166 | O38: =K38*40.46856 -> 15.782738 | P38: =N38-O38 -> 2.023428 | Q38: =P38/O38 -> 0.12820513 | R38: 8.36 | S38: =VLOOKUP(A38,'[1]Kharif tonnage acres2025'!A37:C1828,3,FALSE) -> 6.83 | T38: pichhle sal ki tulna mein is sal dhaan ka fasal mein badhotari hua Hai Kunal bhi achcha hua hai aur Kisan khush hai aur aage bhi Mati purak ka prayog karna chahta hai
A39: 1745396907192 | B39: 939 | C39: 16.25 | D39: 4 | E39: 15 | F39: 1.25 | G39: 0.4 | H39: 0.37 | I39: 0.03 | J39: =G39 -> 0.4 | K39: =H39 -> 0.37 | L39: =J39-K39 -> 0.03 | M39: =L39/K39 -> 0.081081081 | N39: =J39*40.46856 -> 16.187424 | O39: =K39*40.46856 -> 14.973367 | P39: =N39-O39 -> 1.2140568 | Q39: =P39/O39 -> 0.081081081 | R39: 8.74 | S39: =VLOOKUP(A39,'[1]Kharif tonnage acres2025'!A38:C1829,3,FALSE) -> 5.03 | T39: Jis Jis Khet mein matipurak lagaye Hain usmein achcha dhan hua hai or jyada Dhan hua Hai Khet ka Mitti bhi Naram hua Hai or prali bhi lamba, Mota hua Hai
A40: 1748585169654 | B40: 769 | C40: 14.9 | D40: 2 | E40: 14.1 | F40: 0.8 | G40: 0.37 | H40: 0.35 | I40: 0.02 | J40: =G40 -> 0.37 | K40: =H40 -> 0.35 | L40: =J40-K40 -> 0.02 | M40: =L40/K40 -> 0.057142857 | N40: =J40*40.46856 -> 14.973367 | O40: =K40*40.46856 -> 14.163996 | P40: =N40-O40 -> 0.8093712 | Q40: =P40/O40 -> 0.057142857 | R40: 12.07 | S40: =VLOOKUP(A40,'[1]Kharif tonnage acres2025'!A39:C1830,3,FALSE) -> 65 | T40: mati purak ke dalne se fasal par 0.01 ka difference dikh rha hai
...

Sheet Base wise Kharif 2025
A1: Indicator | B1: Description | C1: GPM | D1: Seoni | E1: Pakud | F1: Nainpur | G1: Shahdol
A2: Number of Farmers (N)(With both control and deployed plot) | B2: Total valid observations | C2: 85 | D2: 83 | E2: 32 | F2: 10 | G2: 6
A3: Avg Deployed Yield (q/acre) | B3: Mean yield under MATI | C3: 15.392336 | D3: 16.221554 | E3: 17.565884 | F3: 21.205525 | G3: 31.970162
A4: Avg Control Yield (q/acre) | B4: Mean yield without MATI | C4: 12.418293 | D4: 12.384355 | E4: 15.542456 | F4: 16.106487 | G4: 20.863791
A5: Avg Yield Difference (q/acre) | B5: Mean gain per farmer | C5: 2.9740424 | D5: 3.8371996 | E5: 2.023428 | F5: 5.0990386 | G5: 11.106371
A6: Avg Yield Impact (%) | B6: Mean % change | C6: 0.24582219 | D6: 0.38423372 | E6: 0.13340351 | F6: 0.33171612 | G6: 0.5467073
A7: Median Yield Impact (%) | B7: Robust % impact | C7: 0.23469388 | D7: 0.34615385 | E7: 0.1222421 | F7: 0.2497449 | G7: 0.5642499
A8: Trimmed Mean Impact (%) | B8: Impact excluding extremes | C8: 0.2420452 | D8: 0.36355569 | E8: 0.13340351 | F8: 0.33171612 | G8: 0.5467073
A9: Min Impact (%) | B9: Worst observed impact | C9: 0.068965517 | D9: -0.43902439 | E9: 0.044444444 | F9: 0.064516129 | G9: 0.28082192
A10: Max Impact (%) | B10: Best observed impact | C10: 0.64705882 | D10: 2 | E10: 0.33333333 | F10: 0.75 | G10: 0.734375
A11: Max Yield Deployed Plot(q/acre) | B11: From Crop Cut | C11: 21.583232 | D11: 101.1714 | E11: 21.043651 | F11: 28.732678 | G11: 41.412826
A12: Min Yield Deployed Plot(q/acre) | B12: From Crop Cut | C12: 11.331197 | D12: 6.4749696 | E12: 15.378053 | F12: 13.354625 | G12: 21.987918
A13: Total Tonnage | B13: From Crop Cut | C13: 14890 | D13: 7050 | E13: 418.83 | F13: 910 | G13: 620
A14: Total Acreage | B14: From Crop Cut | C14: 1417.3 | D14: 657.115 | E14: 15.23 | F14: 96.3 | G14: 57.6

Sheet Dataset S1
A1: farmer_id | B1: base_id | C1: site | D1: baseline_yield_qac | E1: treatment_yield_qac | F1: delta_yield_pct | G1: farm_size_acres
A2: 1726729433611 | B2: 1 | C2: GPM | D2: 12.545254 | E2: 15.108262 | F2: 20.430108 | G2: 2.77
A3: 1738229409347 | B3: 4 | C3: Pakur | D3: 18.615538 | E3: 20.638966 | F3: 10.869565 | G3: 0
A4: 1738231639812 | B4: 4 | C4: Pakur | D4: 14.568682 | E4: 16.187424 | F4: 11.111111 | G4: 0
A5: 1747200300435 | B5: 1 | C5: GPM | D5: 9.3077688 | E5: 13.75931 | F5: 47.826087 | G5: 41.45
A6: 1744694039008 | B6: 4 | C6: Pakur | D6: 15.782738 | E6: 16.996795 | F6: 7.6923077 | G6: 0
A7: 1730526661966 | B7: 1 | C7: GPM | D7: 10.38693 | E7: 13.48952 | F7: 29.87013 | G7: 14.32
A8: 1738306257831 | B8: 4 | C8: Pakur | D8: 16.59211 | E8: 18.210852 | F8: 9.7560976 | G8: 0
A9: 1726041387616 | B9: 1 | C9: GPM | D9: 12.275463 | E9: 14.029101 | F9: 14.285714 | G9: 9.09
A10: 1727151811431 | B10: 1 | C10: GPM | D10: 14.433786 | E10: 18.210852 | F10: 26.168224 | G10: 11.73
A11: 1744620291141 | B11: 13 | C11: Nainpur | D11: 16.187424 | E11: 28.327992 | F11: 75 | G11: 6.21
A12: 1743844344980 | B12: 1 | C12: GPM | D12: 9.7124544 | E12: 13.21973 | F12: 36.111111 | G12: 5.36
A13: 1733721019866 | B13: 2 | C13: Seoni | D13: 17.806166 | E13: 24.281136 | F13: 36.363636 | G13: 15.94
... A217: 1746258415029 | B217: 4 | C217: Pakur | D217: 14.568682 | E217: 16.996795 | F217: 16.666667 | G217: 0
